#####
###
Great question! Let me explain how the `error` in try-catch works and who/what sends it.

## Who Sends the Error?

The **error** can come from different sources in your code:

### 1. **Mongoose Library**
```javascript
try {
    const db = await mongoose.connect(process.env.MONGODB_URI || '', {})
    // ↑ If mongoose.connect() fails, mongoose throws an error
} catch (error) {
    // mongoose sent this error
}
```

### 2. **MongoDB Database**
```javascript
// Examples of what can go wrong:
// - Wrong connection string → mongoose throws error
// - Database server is down → MongoDB sends error via mongoose
// - Authentication failed → MongoDB sends error via mongoose  
// - Network timeout → Network layer sends error via mongoose
```

### 3. **JavaScript/Node.js Runtime**
```javascript
try {
    const result = JSON.parse(invalidJSON); // JavaScript throws SyntaxError
} catch (error) {
    // JavaScript runtime sent this error
}
```

## Is Error an Object? YES!

The `error` is indeed an **object** with properties:

### Standard Error Properties:
```javascript
catch (error) {
    console.log(error.name);       // "MongooseError", "ValidationError", etc.
    console.log(error.message);    // Human-readable description
    console.log(error.stack);      // Stack trace showing where error occurred
}
```

### MongoDB/Mongoose Specific Properties:
```javascript
catch (error) {
    console.log(error.name);       // "MongoNetworkError"
    console.log(error.message);    // "connection timed out"
    console.log(error.code);       // MongoDB error code (e.g., 11000)
    console.log(error.codeName);   // "DuplicateKey"
    console.log(error.reason);     // Additional details
}
```

## Real Example - Different Error Scenarios:

```javascript
try {
    // Scenario 1: Wrong connection string
    const db = await mongoose.connect('mongodb://wrong-url', {})
} catch (error) {
    console.log(error.name);    // "MongooseServerSelectionError"
    console.log(error.message); // "connect ENOTFOUND wrong-url"
    // This error comes from: Network layer → Mongoose → Your catch block
}

try {
    // Scenario 2: Authentication failure  
    const db = await mongoose.connect('mongodb://wronguser:wrongpass@localhost/mydb', {})
} catch (error) {
    console.log(error.name);    // "MongoServerError"
    console.log(error.message); // "Authentication failed"
    console.log(error.code);    // 18
    // This error comes from: MongoDB server → Mongoose → Your catch block
}
```

## Error Object Structure:

```javascript
catch (error) {
    console.log(typeof error);  // "object"
    console.log(error);         // Full error object
    
    // Common properties:
    console.log(error.name);       // Error type
    console.log(error.message);    // Error description  
    console.log(error.stack);      // Stack trace
    
    // MongoDB specific (if applicable):
    console.log(error.code);       // MongoDB error code
    console.log(error.codeName);   // MongoDB error name
}
```

## Error Flow:

```
1. You call: mongoose.connect()
2. Mongoose tries to connect to MongoDB
3. Something fails (network, auth, etc.)
4. MongoDB/Network/Mongoose creates an Error object
5. JavaScript throws this Error object
6. Your catch block receives this Error object
```

## You Can Also Create Errors:

```javascript
try {
    if (!process.env.MONGODB_URI) {
        throw new Error("MongoDB URI is required!"); // You create and throw
    }
    const db = await mongoose.connect(process.env.MONGODB_URI, {})
} catch (error) {
    // Could be your error OR mongoose's error
    console.log(error.message);
}
```

So yes, `error` is an object with properties, and it can come from various sources - the database, the mongoose library, the network, or even your own code!


